Workbook

Sheet Form blank
A1: PHIẾU YÊU CẦU BÁO GIÁ HÀNG GIÁN TIẾP
A2: Indirect Goods Quotation Request Form
B4: Ngày/tháng Date/month(*) | H4: Số đơn yêu cầu báo giá Quotation Request Number
A6: Dòng chảy form: PIC phòng ban có yêu cầu > Quản lý sơ cấp > Quản lý trung cấp > PIC Pur > Quản lý sơ cấp Pur フォーム流れ: 要求課PIC > 要求課初級管理職 > 要求課中級管理職 > Pur課PIC > Pur課係長 | J6: XEM LẠI VÍ DỤ ĐIỀN FORM SHEET "INPUT FORM (EX)"
A7: 1 | B7: 2 | C7: 3 | D7: 4 | E7: 5 | F7: 6 | G7: 7 | H7: 8 | I7: 9 | J7: 10 | K7: 11 | L7: 12 | M7: =L7+1 -> 13 | S7: 14 | T7: =S7+1 -> 15 | U7: =T7+1 -> 16 | V7: =U7+1 -> 17 | W7: =V7+1 -> 18 | X7: =W7+1 -> 19 | Y7: =X7+1 -> 20 | Z7: =Y7+1 -> 21 | AA7: =Z7+1 -> 22 | ... AH7: =AG7+1 -> 29
A8: No | B8: Request section code(*) mã phòng ban | C8: Section (*) Tên phòng | D8: Phân loại Category (A/E/non list) | E8: Mã thiết bị Equipment code | F8: Mã hàng nội bộ BIVN's part code | G8: Mã hàng của NCC Vendor's good code | H8: Tên hàng VN(*) Part name (Vietnamese) | I8: Tên hàng tiếng anh(*) Part name (English) | J8: Số lượng Quanlity(*) | K8: Đơn vị Unit(*) | L8: Chủng loại hàng Part category | M8: Mô tả hàng hóa Description of goods | S8: Yêu cầu ROHS ROHS requirements | T8: Yêu cầu CO/CQ CO/Cqrequirements | U8: Yêu cầu MSDS kèm số CAS (đối với hóa chất) Request MSDS with CAS number (for chemicals) | V8: Yêu cầu tiêu chuẩn an toàn Request for safety standards | W8: File Thiết kế Design(*) Nếu không có điền NO Need | X8: Nhà Sản xuất Maker | Y8: Mã nhà cung cấp Vendor code | Z8: Tên nhà cung cấp Vendor name | AA8: Lấy báo giá? Is it a quotation request(*) | AB8: Lý do không lấy báo giá Reason for not making a request | AC8: Ngày muốn nhận hàng Desired delivery date(*) | AD8: Kỳ hạn lựa chọn NCC Deadline for deciding vendor(*) | AE8: GẤP urgent | AF8: Người yêu cầu Request person in charge | AG8: Lí do xin báo giá Reason for requesting a quote | AH8: Link ảnh or file thiết kế ( Không cần bảo mật) Link to image or design file (No need to keep it confidential)
M9: Hình dáng Shape | N9: Chất liệu Material | O9: Thành phần, hàm lượng (đối với hóa chất) Composition, Content (for Chemicals) | P9: Kích thước(mm) (dài/rộng/cao) Dimensions (mm) (Length/Width/Height) | Q9: Dùng cho máy/thiết bị/vị trí nào Which machine/equipment/location is it used for | R9: Dùng đề làm gì (tính năng) Purpose of use (or function)
A10: 1 | C10: =VLOOKUP(B10,Master!A:B,2,0) -> #N/A | AA10: O
A11: 2 | C11: =VLOOKUP(B11,Master!A:B,2,0) -> #N/A | AA11: O
A12: 3 | C12: =VLOOKUP(B12,Master!A:B,2,0) -> #N/A | AA12: O
A13: 4 | C13: =VLOOKUP(B13,Master!A:B,2,0) -> #N/A | AA13: O
A14: 5 | C14: =VLOOKUP(B14,Master!A:B,2,0) -> #N/A | AA14: O
A15: 6 | C15: =VLOOKUP(B15,Master!A:B,2,0) -> #N/A | AA15: O
A16: 7 | C16: =VLOOKUP(B16,Master!A:B,2,0) -> #N/A | AA16: O
A17: 8 | C17: =VLOOKUP(B17,Master!A:B,2,0) -> #N/A | AA17: O
A18: 9 | C18: =VLOOKUP(B18,Master!A:B,2,0) -> #N/A | AA18: O
A19: 10 | C19: =VLOOKUP(B19,Master!A:B,2,0) -> #N/A | AA19: O
A20: 11 | C20: =VLOOKUP(B20,Master!A:B,2,0) -> #N/A | AA20: O
A21: 12 | C21: =VLOOKUP(B21,Master!A:B,2,0) -> #N/A | AA21: O
... A569: 560 | C569: =VLOOKUP(B569,Master!A:B,2,0) -> #N/A | AA569: O

Sheet フォーム説明
E1: Hàng cũ đang/đã sử dụng 注文した部品 | F1: Hàng mới (chưa nhập về BIVN bao giờ) 新設部品
B2: Ngày 日付(*) | E2: Hàm tự động公式 | F2: Hàm tự động公式
B3: Số đơn | E3: Hàm tự động公式 | F3: Hàm tự động公式 | G3: RQ-nămthángngay-Số thứ tự đơn trong ngày
B4: 1 | C4: No | E4: Bắt buộc điền 必要 | F4: Bắt buộc điền 必要
B5: 2 | C5: Request section code(*) mã phòng ban | E5: Bắt buộc điền 必要 | F5: Bắt buộc điền 必要
B6: 3 | C6: Section (*) Tên phòng | E6: Hàm tự động公式 | F6: Hàm tự động公式 | G6: Link theo mã phòng 部署コードによるリンク
B7: 4 | C7: Phân loại Category (A/E/non list) | E7: Hàm tự động公式 | F7: Bắt buộc điền 必要 | G7: Mã cũ: Link theo master Mã mới: Chọn A,E,Ngoài danh mục 旧コード：マスターによるリンク 新コード：A、E、カテゴリ外を選択
B8: 5 | C8: Mã thiết bị Equipment code | E8: Không bắt buộc （不要） | F8: Không bắt buộc （不要） | G8: Phòng nào cần quản lý theo 1 thiết bị hoặc 1 khuôn (như RD PE hoặc MPE) thì điền mã thiết bị hoặc mã khuôn vào cột này. Mục đích sau này hệ thống sẽ phát triển là có thể check được giá cho cả thiết bị khi lấy đủ báo giá các mặt hàng nhỏ dùng lắp lên nó RD PEやMPEのように、1つの設備または1つの金型で管理する必要がある部門は、この列に設備コードまたは金型コードを入力してください。 将来的には、システムを拡張し、関連する小部品の見積もりが揃った際に、設備全体の価格を確認できるようにすることを目的としています。
B9: 6 | C9: Mã hàng nội bộ BIVN's part code | E9: Bắt buộc điền 必要 | F9: Không bắt buộc （不要） | G9: Hiện tại có mã nội bộ cho hàng A và E Sau đây thì cả hàng ngoài danh mục cũng sẽ thực hiện tạo mã nội bộ 現在、A品とE品には社内コードがあります。 今後は、リスト外の商品についても社内コードを作成します。
B10: 7 | C10: Mã hàng của NCC Vendor's good code | E10: Hàm tự động公式 | F10: Bắt buộc điền 必要 | G10: Với hàng thị trường bán đại trà : chính là mã/đời model hàng hóa mà NCC đăng trong danh mục hàng hóa trên Web Với hàng tự thiết kế (BIVN/hay NCC): dùng code bản vẽ 市場で一般販売されている商品については、サプライヤーがWeb上の商品リストに掲載している商品コード／モデル番号を使用します。 自社設計品（BIVNまたはサプライヤー）の場合は、図面コードを使用します。
B11: 8 | C11: Tên hàng VN dùng để mở thủ tục hải quan (dự thảo)(*) Part name (Vietnamese) | E11: Hàm tự động公式 | F11: Bắt buộc điền 必要 | G11: Mã đã mua: Vlook up theo master Mã mới: Ghi tên tiếng Việt tự đặt dựa vào phần mô tả hàng hóa 旧コード：マスターに基づくVlook up 新コード：商品の説明に基づいて自分で設定したベトナム語名を記入 Cột này chỉ là tên dự thảo của phòng ban, sau Ship sẽ xác nhận lại trước khi phát hành đơn yêu cầu hàng hóa 商品の説明部分の関数＆。通関手続きの名称は使用目的によって変更されます。 この列は部門による仮の名称であり、出荷後に購買依頼書を発行する前に確認されます。
B12: 9 | C12: Tên hàng tiếng anh(*) Part name (English) | E12: Hàm tự động公式 | F12: Bắt buộc điền 必要
B13: 10 | C13: Số lượng Quanlity(*) | E13: Bắt buộc điền 必要 | F13: Bắt buộc điền 必要
B14: 11 | C14: Đơn vị Unit(*) | E14: Bắt buộc điền 必要 | F14: Bắt buộc điền 必要
B15: 12 | C15: Chủng loại hàng Part category | E15: Hàm tự động公式 | F15: Bắt buộc điền 必要 | G15: Mã mới: Lựa chọn trong chủng loại hàng hóa trong master, nếu phát sinh chủng loại mới cần phải liên lạc Pur tạo master thì mới có thể lựa chọn 新コード：マスター内の品目カテゴリから選択、新しいカテゴリが発生した場合は、選択する前にPurに連絡してマスターを作成する必要があります。
B16: =B15+1 -> 13 | C16: Mô tả hàng hóa Description of goods | D16: Hình dáng Shape | E16: Hàm tự động公式 | F16: Bắt buộc điền 必要 | G16: Ví dụ : tấm, khay , hộp, giá đỡ, tên thiết bị, tên dụng cụ... Chú ý: Có thể gắn thêm ảnh mô tả nhưng vẫn phải mô tả bằng ngôn ngữ Mã đã mua: Link luôn tên hàng dùng để mở hải quan cũ 例: プレート、トレー、ボックス、ホルダー、機器名、ツール名など 注意: 説明文に言語を使用する必要があるが、説明用の画像を追加することも可能 購入済みコード：旧税関を開けるために使用した商品の名前をリンクする
D17: Chất liệu Material | E17: Không bắt buộc （不要） | F17: Bắt buộc điền 必要 | G17: Ví dụ: inox, nhựa... Nếu có nhiều loại NVL thì ghi 1 vài NVL chính cấu thành (chiếm tầm 80~90%) Mã đã mua: Để trống 例: ステンレス、プラスチックなど 複数の材料がある場合は、主な構成材料（全体の約80〜90％を占めるもの）をいくつか記載してください。 購入済みコード：空欄のままにする
D18: Thành phần, hàm lượng (đối với hóa chất) Composition, Content (for Chemicals) | E18: Không bắt buộc （不要） | F18: Bắt buộc điền 必要 | G18: nếu chưa có MSDS thì tra trên mạng và ghi thành phần chính (sao cho chiếm 90% tổng số Mã đã mua: Để trống MSDSがない場合は、インターネットで調べて主な成分（全体の90%を占めるもの）を記載してください。 旧コード：空欄のままにする
D19: Kích thước(mm) (dài/rộng/cao) Dimensions (mm) (Length/Width/Height) | E19: Không bắt buộc （不要） | F19: Bắt buộc điền 必要 | G19: Viết đúng theo thứ tự quy định , đơn vị mm Mã đã mua: Để trống 規定された順序に従って正しく記入し、単位はmmで記載してください。 旧コード：空欄のままにする
D20: Dùng cho máy/thiết bị/vị trí nào Which machine/equipment/location is it used for | E20: Tùy đối tượng | F20: Bắt buộc điền 必要 | G20: ví dụ: máy A, vị trí thao tác lắp cụm frame.... Mã đã mua: Nếu không thay đổi thì copy sang 例: A機械、フレームユニットを取り付ける作業位置... 旧コード：変更がない場合はコピーしてください
D21: Dùng đề làm gì (tính năng) Purpose of use (or function) | E21: Tùy đối tượng | F21: Bắt buộc điền 必要 | G21: 例: 携帯電話からパソコンに接続する、通路と射出成形機の間に障害物がある… 旧コード：変更がない場合はコピーしてください
B22: 14 | C22: Yêu cầu ROHS ROHS requirements | E22: Không bắt buộc （不要） | F22: Không bắt buộc （不要） | G22: Tuỳ yêu cầu phòng ban 部門の要求に応じて Cần điền "O", Không cần bỏ trống
B23: =B22+1 -> 15 | C23: Yêu cầu CO/CQ CO/Cqrequirements | E23: Không bắt buộc （不要） | F23: Không bắt buộc （不要） | G23: Tuỳ yêu cầu phòng ban 部門の要求に応じて Cần điền "O", Không cần bỏ trống
B24: =B23+1 -> 16 | C24: Yêu cầu MSDS kèm số CAS (đối với hóa chất) Request MSDS with CAS number (for chemicals) | E24: Không bắt buộc （不要） | F24: Không bắt buộc （不要） | G24: Tuỳ yêu cầu phòng ban 部門の要求に応じて Cần điền "O", Không cần bỏ trống
B25: =B24+1 -> 17 | C25: Yêu cầu tiêu chuẩn an toàn Request for safety standards | E25: Không bắt buộc （不要） | F25: Không bắt buộc （不要） | G25: Tuỳ yêu cầu phòng ban 部門の要求に応じて Cần điền "O", Không cần bỏ trống
B26: =B25+1 -> 18 | C26: File Thiết kế Design(*) | E26: Tùy đối tượng | F26: Bắt buộc điền 必要 | G26: 1 chủng loại linh kiện 1 link BOX kèm mật khẩu 1種類の部品につき1つのBOXリンクとパスワードを付けてください Hàng ngoài danh mục thì cũ hay mới đều bắt buộc Hàng thị trường thì không cần
B27: =B26+1 -> 19 | C27: Nhà Sản xuất Maker | E27: Hàm tự động公式 | F27: Bắt buộc điền 必要 | G27: Điền tên nhãn hãng sản xuất cho mã hàng đó その商品コードに対してメーカー名を記入してください
B28: =B27+1 -> 20 | C28: Mã nhà cung cấp Vendor code | E28: Hàm tự động公式 | F28: Hàm tự động公式 | G28: Link từ cột chủng loại hàng+master 品目カテゴリー+マスターからのリンク
B29: =B28+1 -> 21 | C29: Tên nhà cung cấp Vendor name | E29: Hàm tự động公式 | F29: Hàm tự động公式 | G29: Link từ cột chủng loại hàng+master 品目カテゴリー+マスターからのリンク
B30: =B29+1 -> 22 | C30: Lấy báo giá? Is it a quotation request(*) | E30: Bắt buộc điền 必要 | F30: Bắt buộc điền 必要 | G30: O: cần lấy báo giá X: Không cần Nếu Không muốn lấy báo gía NCC nào thì PIC tự đổi thành X dòng tương ứng tên NCC đó O: 見積りが必要 X: 必要なし 特定の仕入先から見積りを取りたくない場合は、担当者がその仕入先名に対応する行をXに変更してください
B31: =B30+1 -> 23 | C31: Lý do không lấy báo giá Reason for not making a request | E31: Bắt buộc điền 必要 | F31: Bắt buộc điền 必要 | G31: Chỉ Điền lý do hợp lý với các NCC chọn X ở cột số 22 các dòng tick "O" thì ko cần 列22で「X」を選択した仕入先には、合理的な理由のみ記入してください。 「O」をチェックした行については必要ありません。
B32: =B31+1 -> 24 | C32: Ngày muốn nhận hàng Desired delivery date(*) | E32: Bắt buộc điền 必要 | F32: Bắt buộc điền 必要
B33: =B32+1 -> 25 | C33: Kỳ hạn lựa chọn NCC Deadline for deciding vendor(*) | E33: Bắt buộc điền 必要 | F33: Bắt buộc điền 必要 | G33: Gấp : 3 ngày Thông thường : 3 ngày làm việc/10 linh kiện Chỉ tính từ khi có đủ thông tin lấy báo giá 緊急: 3日 通常: 3営業日/10部品 見積取得に必要な情報が揃ってからカウントします。
B34: =B33+1 -> 26 | C34: GẤP urgent | E34: Không bắt buộc （不要） | F34: Không bắt buộc （不要） | G34: Gấp thì tick O không thi bỏ trống 緊急の場合は「O」を入れ、それ以外は空欄にしてください。
B35: =B34+1 -> 27 | C35: Người yêu cầu Request person in charge | E35: Không bắt buộc （不要） | F35: Không bắt buộc （不要） | G35: Phòng ban nào cần quản lý thông tin người đưa yêu cầu thì điền, còn không thì bỏ trống 要求者の情報を管理する必要がある部署は記入してください。それ以外の場合は空欄にしてください。

Sheet Input form (ex)
B1: Phải điền | C1: Không cần điền | E1: Có nhu cầu thì điền | F1: Đọc lại điều kiện
A3: 1. Mã cũ (mã đã có trong file master).
A4: 1 | B4: 2 | C4: 3 | D4: 4 | E4: 5 | F4: 6 | G4: 7 | H4: 8 | I4: 9 | J4: 10 | K4: 11 | L4: 12 | M4: =L4+1 -> 13 | S4: 14 | T4: =S4+1 -> 15 | U4: =T4+1 -> 16 | V4: =U4+1 -> 17 | W4: =V4+1 -> 18 | X4: =W4+1 -> 19 | Y4: =X4+1 -> 20 | Z4: =Y4+1 -> 21 | AA4: =Z4+1 -> 22 | ... AF4: =AE4+1 -> 27 | AG4: 28
A5: No | B5: Request section code(*) mã phòng ban | C5: Section (*) Tên phòng | D5: Phân loại Category (A/E/non list) | E5: Mã thiết bị Equipment code | F5: Mã hàng nội bộ BIVN's part code | G5: Mã hàng của NCC Vendor's good code | H5: Tên hàng VN dùng để mở thủ tục hải quan (dự thảo)(*) Part name (Vietnamese) | I5: Tên hàng tiếng anh(*) Part name (English) | J5: Số lượng Quanlity(*) | K5: Đơn vị Unit(*) | L5: Chủng loại hàng Part category | M5: Mô tả hàng hóa Description of goods | S5: Yêu cầu ROHS ROHS requirements | T5: Yêu cầu CO/CQ CO/Cqrequirements | U5: Yêu cầu MSDS kèm số CAS (đối với hóa chất) Request MSDS with CAS number (for chemicals) | V5: Yêu cầu tiêu chuẩn an toàn Request for safety standards | W5: File Thiết kế Design(*) | X5: Nhà Sản xuất Maker | Y5: Mã nhà cung cấp Vendor code | Z5: Tên nhà cung cấp Vendor name | AA5: Lấy báo giá? Is it a quotation request(*) | AB5: Lý do không lấy báo giá Reason for not making a request | AC5: Ngày muốn nhận hàng Desired delivery date(*) | AD5: Kỳ hạn lựa chọn NCC Deadline for deciding vendor(*) | AE5: GẤP urgent | AF5: Người yêu cầu Request person in charge | AG5: Lí do xin báo giá Reason for quotation request
M6: Hình dáng Shape | N6: Chất liệu Material | O6: Thành phần, hàm lượng (đối với hóa chất) Composition, Content (for Chemicals) | P6: Kích thước(mm) (dài/rộng/cao) Dimensions (mm) (Length/Width/Height) | Q6: Dùng cho máy/thiết bị/vị trí nào Which machine/equipment/location is it used for | R6: Dùng đề làm gì (tính năng) Purpose of use (or function)
A7: 1 | B7: 3110 | C7: =VLOOKUP(B7,[1]Master!D:E,2,0) -> #N/A | F7: O00000863 | H7: =L7&"có hình dáng dạng "&M7&" chất liệu "&N7&" thành phần hóa chất: "&O7&" có kích thước "&P7&" dùng để "&R7&" cho "&Q7 -> có hình dáng dạng chất liệu thành phần hóa chất: có kích thước dùng để cho | J7: 10 | W7: Nếu là mã ngoài danh mục có thiết kế: Phải đính kèm | AA7: X | AC7: 46143 | AD7: 46132
A8: 2 | B8: 3110 | C8: =VLOOKUP(B8,[1]Master!D:E,2,0) -> #N/A | F8: O00000864 | H8: =L8&"có hình dáng dạng "&M8&" chất liệu "&N8&" thành phần hóa chất: "&O8&" có kích thước "&P8&" dùng để "&R8&" cho "&Q8 -> có hình dáng dạng chất liệu thành phần hóa chất: có kích thước dùng để cho | J8: 10 | W8: Nếu là mã tiêu chuẩn: Không cần | AA8: O | AC8: 46143 | AD8: 46132
A9: 3 | B9: 3110 | C9: =VLOOKUP(B9,[1]Master!D:E,2,0) -> #N/A | F9: O00000865 | H9: =L9&"có hình dáng dạng "&M9&" chất liệu "&N9&" thành phần hóa chất: "&O9&" có kích thước "&P9&" dùng để "&R9&" cho "&Q9 -> có hình dáng dạng chất liệu thành phần hóa chất: có kích thước dùng để cho | J9: 10 | W9: Nếu là sữar chữa/bảo dưỡng/thi công...: cần copy link format PL12 hoặc PL13 | AA9: O | AC9: 46143 | AD9: 46132
H10: =M10&" "&N10&" "&O10&""&P10&" "&Q10&" "&R10
H11: =M11&" "&N11&" "&O11&""&P11&" "&Q11&" "&R11
A12: 2. Mã mới : Chưa mua bao giờ
A13: 1 | B13: 2 | C13: 3 | D13: 4 | E13: 5 | F13: 6 | G13: 7 | H13: 8 | I13: 9 | J13: 10 | K13: 11 | L13: 12 | M13: =L13+1 -> 13 | S13: 14 | T13: =S13+1 -> 15 | U13: =T13+1 -> 16 | V13: =U13+1 -> 17 | W13: =V13+1 -> 18 | X13: =W13+1 -> 19 | Y13: =X13+1 -> 20 | Z13: =Y13+1 -> 21 | AA13: =Z13+1 -> 22 | ... AF13: =AE13+1 -> 27 | AG13: 28
A14: No | B14: Request section code(*) mã phòng ban | C14: Section (*) Tên phòng | D14: Phân loại Category (A/E/non list) | E14: Mã thiết bị Equipment code | F14: Mã hàng nội bộ BIVN's part code | G14: Mã hàng của NCC Vendor's good code | H14: Tên hàng VN dùng để mở thủ tục hải quan (dự thảo)(*) Part name (Vietnamese) | I14: Tên hàng tiếng anh(*) Part name (English) | J14: Số lượng Quanlity(*) | K14: Đơn vị Unit(*) | L14: Chủng loại hàng Part category | M14: Mô tả hàng hóa Description of goods | S14: Yêu cầu ROHS ROHS requirements | T14: Yêu cầu CO/CQ CO/Cqrequirements | U14: Yêu cầu MSDS kèm số CAS (đối với hóa chất) Request MSDS with CAS number (for chemicals) | V14: Yêu cầu tiêu chuẩn an toàn Request for safety standards | W14: File Thiết kế Design(*) | X14: Nhà Sản xuất Maker | Y14: Mã nhà cung cấp Vendor code | Z14: Tên nhà cung cấp Vendor name | AA14: Lấy báo giá? Is it a quotation request(*) | AB14: Lý do không lấy báo giá Reason for not making a request | AC14: Ngày muốn nhận hàng Desired delivery date(*) | AD14: Kỳ hạn lựa chọn NCC Deadline for deciding vendor(*) | AE14: GẤP urgent | AF14: Người yêu cầu Request person in charge | AG14: Lí do xin báo giá Reason for quotation request
M15: Hình dáng Shape | N15: Chất liệu Material | O15: Thành phần, hàm lượng (đối với hóa chất) Composition, Content (for Chemicals) | P15: Kích thước(mm) (dài/rộng/cao) Dimensions (mm) (Length/Width/Height) | Q15: Dùng cho máy/thiết bị/vị trí nào Which machine/equipment/location is it used for | R15: Dùng đề làm gì (tính năng) Purpose of use (or function)
A16: 1 | B16: 3110 | C16: =VLOOKUP(B16,[1]Master!D:E,2,0) -> #N/A | H16: =L16&"có hình dáng dạng "&M16&" chất liệu "&N16&" thành phần hóa chất: "&O16&" có kích thước "&P16&" dùng để "&R16&" cho "&Q16 -> có hình dáng dạng chất liệu thành phần hóa chất: có kích thước dùng để cho | J16: 10 | K16: cái/chiếc | W16: Nếu là mã ngoài danh mục có thiết kế: Phải đính kèm | AA16: X | AC16: 46143 | AD16: 46132
A17: 2 | B17: 3110 | C17: =VLOOKUP(B17,[1]Master!D:E,2,0) -> #N/A | H17: =L17&"có hình dáng dạng "&M17&" chất liệu "&N17&" thành phần hóa chất: "&O17&" có kích thước "&P17&" dùng để "&R17&" cho "&Q17 -> có hình dáng dạng chất liệu thành phần hóa chất: có kích thước dùng để cho | J17: 10 | K17: cái/chiếc | W17: Nếu là mã tiêu chuẩn: Không cần | AA17: O | AC17: 46143 | AD17: 46132
A18: 3 | B18: 3110 | C18: =VLOOKUP(B18,[1]Master!D:E,2,0) -> #N/A | H18: =L18&"có hình dáng dạng "&M18&" chất liệu "&N18&" thành phần hóa chất: "&O18&" có kích thước "&P18&" dùng để "&R18&" cho "&Q18 -> có hình dáng dạng chất liệu thành phần hóa chất: có kích thước dùng để cho | J18: 10 | K18: cái/chiếc | W18: Nếu là sữar chữa/bảo dưỡng/thi công...: cần copy link format PL12 hoặc PL13 | AA18: O | AC18: 46143 | AD18: 46132
A19: 3 | B19: 3110 | C19: =VLOOKUP(B19,[1]Master!D:E,2,0) -> #N/A | H19: =L19&"có hình dáng dạng "&M19&" chất liệu "&N19&" thành phần hóa chất: "&O19&" có kích thước "&P19&" dùng để "&R19&" cho "&Q19 -> có hình dáng dạng chất liệu thành phần hóa chất: có kích thước dùng để cho | J19: 10 | K19: cái/chiếc | W19: Nếu là sữar chữa/bảo dưỡng/thi công...: cần copy link format PL12 hoặc PL13 | AA19: O | AC19: 46143 | AD19: 46132
B20: Up ngoài phần lựa chọn >> báo lỗi ko up được | D20: Up ngoài phần lựa chọn >> báo lỗi ko up được | K20: Up ngoài phần lựa chọn >> báo lỗi ko up được | L20: Không được để trống | M20: Phải điền, với hàng dịch vụ ghi "-" | N20: Phải điền, với hàng dịch vụ ghi "-" | O20: Phải điền, với hàng dịch vụ ghi "-" | P20: Phải điền, với hàng dịch vụ ghi "-" | Q20: Phải điền, với hàng dịch vụ ghi "-" | R20: Phải điền, với hàng dịch vụ ghi "-" | Y20: hệ thống báo lỗi file nếu PIC cố tình thêm NCC ko có trong MAP tương ứng chủng loại (VD: chủng loại A chỉ có 2 vendor , PIC cố tình add thêm vendor 3 >> báo lỗi ko cho up)
L21: phải có trong MAP | Y21: Điền tay mà điền sai vendor code ko có trong MAP >> báo lỗi ko cho up

Sheet Master
A1: Mã phòng | B1: tên phòng | D1: Unit | H1: Material_Code | I1: Material_Name_VN
A2: 1110 | B2: GA-GA-CANTEEN | D2: Ao/xơ
A3: 1120 | B3: ADM-PER-EC SAL | D3: Ao/xơ (gồm bao bì) | H3: A000001 | I3: Giầy chống tĩnh điện
A4: 1130 | B4: GA-GA-DORMITORY | D4: Ao/xơ (gồm cont.) | H4: A000002 | I4: Giầy an toàn
A5: 1210 | B5: GA-GA | D5: Ao/xơ (hàm lượng KL) | H5: A000003 | I5: Túi nhựa bọc giầy
A6: 1211 | B6: ADM-PER | D6: Ao/xơ (trọng lg khô) | H6: A000004-L | I6: Đồng phục đặc biệt Size L
A7: 1212 | B7: GA-SFE | D7: Ao/xơ đong | H7: A000004-M | I7: Đồng phục đặc biệt Size M
A8: 1220 | B8: GA-FAC | D8: Bản | H8: A000004-S | I8: Đồng phục đặc biệt Size S
A9: 1221 | B9: TT Factory GA COMMON | D9: Bảng | H9: A000004-XL | I9: Đồng phục đặc biệt Size XL
A10: 1221 | B10: TT Factory GA COMMON | D10: Barrel | H10: A000004-XXL | I10: Đồng phục đặc biệt Size XXL
A11: 1221 | B11: TT Factory GA COMMON | D11: Bịch | H11: A000005-L | I11: Đồng phục đặc biệt Size L
A12: 1310 | B12: ADM-ACC | D12: Bộ | H12: A000005-M | I12: Đồng phục đặc biệt Size M
A13: 1410 | B13: ADM-MP | D13: Cái/Chiếc | H13: A000005-S | I13: Đồng phục đặc biệt Size S
A14: 1910 | B14: Office Common IM | D14: Cành | H14: A000005-XL | I14: Đồng phục đặc biệt Size XL
... A65: 8110 | B65: Strategy Promotion section | D65: Mili lít | H65: A000047 | I65: Băng dính dán nền trắng 5cm*32m (32m/ Roll)
A66: A002 | B66: PR1-PR1-BLL SCANNER | D66: Mili mét | H66: A000048 | I66: Băng dính dán nền vàng 5cm*25m (25m/ Roll)
A67: A003 | B67: PR1-PR1-BL SCANNER | D67: mm2 | H67: A000049 | I67: Băng dính trong 48mm*70Y
A68: A004 | B68: PR1-PR1-DSL SCANNER | D68: mm3 | H68: A000050 | I68: Băng dính trong 1.8cm
A69: A005 | B69: PR1-PR1-DLL SCANNER | D69: Nghìn | H69: A000051 | I69: Băng dính 2 mặt 1cm
A70: A006 | B70: PR1-PR1-DL SCANNER | D70: Ống | H70: A000052 | I70: Băng dính 2 mặt 2cm
A71: A007 | B71: PR1-PR１-ELL SCANNER | D71: Panh | H71: A000053 | I71: Băng dính xốp 2 mặt 48mm
A72: A008 | B72: PR1-PR１-EL SCANNER | D72: Pao | H72: A000054 | I72: Băng dính cách điện 2cm (18-20m/roll)
A73: A009 | B73: PR2-PR5-FC SCANNER | D73: Pao (gồm bao bì) | H73: A000055 | I73: Nam châm lá A4
A74: A010 | B74: PR1-PR1-ESL SCANNER | D74: Pao (gồm container) | H74: A000056-L | I74: Đồng phục đặc biệt Size L (Phòng sạch - vàng)
A75: B003 | B75: PR1-PR1-BLL | D75: Pao (hàm lượng KL) | H75: A000056-M | I75: Đồng phục đặc biệt Size M (Phòng sạch - vàng)
A76: B004 | B76: PR1-PR3-BL | D76: Pao (trọng lg khô) | H76: A000056-S | I76: Đồng phục đặc biệt Size S (Phòng sạch - vàng)
A77: B005 | B77: PR2-PR2-DSL | D77: Phút | H77: A000056-XL | I77: Đồng phục đặc biệt Size XL (Phòng sạch - vàng)
... A112: Y0122312 | B112: ELL Project Development engineering | D112: Pallet | H112: A000091 | I112: Mỏ hàn
A113: Y0122313 | B113: ELL Project Manufacturing engineering | H113: A000092 | I113: Mỏ hàn T18-B
A114: Y0123110 | B114: ELL Project Purchasing | H114: A000093-15 | I114: Kim chiết keo ( Xanh) PNC-15G-13
A115: Y0123210 | B115: ELL Project Shipping | H115: A000093-17 | I115: Kim chiết keo (Đen) PNC-17G-13
A116: Y0123310 | B116: ELL Project Prd Control | H116: A000093-18 | I116: Kim chiết keo (Trắng) PNC-18G-13
A117: Y0123320 | B117: ELL Project Material Control | H117: A000094 | I117: Lọc khí A1309
A118: Y0123410 | B118: ELL Project SEM | H118: A000095 | I118: Đầu vặn vít dùng cho máy vặn vít (10 cái/bộ) 37S275
A119: Y0124110 | B119: ELL Project QA | H119: A000096 | I119: Bóng đèn tiết kiệm T5
A120: Y0124210 | B120: ELL Project IQC | H120: A000097 | I120: Gá kẹp đầu vít 400 (469-7642)
A121: Y0124230 | B121: ELL Project SQC | H121: A000098 | I121: Dây dẫn keo AA30N
A122: Y0125160 | B122: ELL Project MPE-ME | H122: A000099 | I122: Công tắc tra dầu VS14
A123: Y0127120 | B123: ELL Project EPE-EE | H123: A000100 | I123: Đầu đo của máy đo điện trở
A124: Y012A007 | B124: ELL Project scanner | H124: A000101 | I124: Đầu đo
...

Sheet Sheet4
C2: Thẩm tra審査 | G2: Dự thảo 起案
C3: QLSC phòng Pur 購買係長 | D3: PIC phòng Pur 購買スタッフ | E3: QLTC phòng ban 中級管理職 | F3: QLSC phòng ban 要求課係長 | G3: PIC phòng ban 要求課スタッフ
